Workbook

Sheet Reading guide, SIGN of NPS
B1: How to interpret NPS scores
B3: NPS is a calculated score:
B4: • Calculated based on three subgroups (see visual)
B5: • Lower number of completes per group means more fluctuations
B6: • Significance testing needs to be on promoters and detractors, so
B7: differences on NPS from one to another quarter are hardly ever significant (see more info on sig. testing below)
B10: Manage fluctuations:
B11: • Increased sample sizes for more stability. Key objective of BAM is to measure brand performance among general population, so not all brands have an equal number of clients (base for NPS). Fewer clients causes higher error margin, especially for NPS.
B12: • 6-months average. Because it is too expensive to enlarge total sample for NPS purposes only, we report a average of six months to increase base size. Error margin remains quite large in countries where the market share of ING is limited (also applicable to competition).
B15: Ranking NPS performance:
B16: In markets with limited differentiation, slight change can create totally different rankings. In fact, this could be caused by the error margin of NPS and not due to actual change. The NPS rankings need to be interpreted with this in mind.
B19: Significance of NPS scores
... B27: Rough estimated delta required before NPS change is significant (95% confidence):
C30: Base size | D30: Delta required (assum. NPS=0) | E30: Delta required (assum. NPS=35) | F30: Delta required (assum. NPS=65)
C31: 50 | D31: 30.441649 | E31: 28.065814 | F31: 22.490453
C32: 100 | D32: 21.525497 | E32: 19.845527 | F32: 15.903152
C33: 150 | D33: 17.575494 | E33: 16.203805 | F33: 12.984869
C34: 200 | D34: 15.220825 | E34: 14.032907 | F34: 11.245226
C35: 300 | D35: 12.427751 | E35: 11.45782 | F35: 9.181689
C36: 400 | D36: 10.762748 | E36: 9.9227636 | F36: 7.9515759
C37: 500 | D37: 9.6264947 | E37: 8.8751896 | F37: 7.1121057
C38: 700 | D38: 8.1358729 | E38: 7.5009042 | F38: 6.0108264
C39: 1000 | D39: 6.8069597 | E39: 6.2757067 | F39: 5.0290182

Sheet Quarterly overview new
B2: Source: Global NPS tracking / Toluna | D2: Q4 - 2025
B4: Australia | D4: NPS | E4: Rank | F4: n
B5: ING | D5: ='Australia (quarter)'!C6 -> #REF! | E5: ='Australia (quarter)'!C49 -> #REF! | F5: ='Australia (quarter)'!C56 -> #REF!
B6: ANZ | D6: ='Australia (quarter)'!C14 -> #REF! | E6: ='Australia (quarter)'!C50 -> #REF! | F6: ='Australia (quarter)'!C57 -> #REF!
B7: Commonwealth Bank | D7: ='Australia (quarter)'!C21 -> #REF! | E7: ='Australia (quarter)'!C51 -> #REF! | F7: ='Australia (quarter)'!C58 -> #REF!
B8: NAB (National Australia Bank) | D8: ='Australia (quarter)'!C28 -> #REF! | E8: ='Australia (quarter)'!C52 -> #REF! | F8: ='Australia (quarter)'!C59 -> #REF!
B9: Westpac | D9: ='Australia (quarter)'!C35 -> #REF! | E9: ='Australia (quarter)'!C53 -> #REF! | F9: ='Australia (quarter)'!C60 -> #REF!
B11: Belgium | D11: NPS | E11: Rank | F11: n
B12: ING | D12: ='Belgium (quarter)'!C35 -> #REF! | E12: ='Belgium (quarter)'!C41 -> #REF! | F12: ='Belgium (quarter)'!C47 -> #REF!
B13: Belfius | D13: ='Belgium (quarter)'!C36 -> #REF! | E13: ='Belgium (quarter)'!C42 -> #REF! | F13: ='Belgium (quarter)'!C48 -> #REF!
B14: BNP Paribas Fortis | D14: ='Belgium (quarter)'!C37 -> #REF! | E14: ='Belgium (quarter)'!C43 -> #REF! | F14: ='Belgium (quarter)'!C49 -> #REF!
B15: KBC/CBC | D15: ='Belgium (quarter)'!C38 -> #REF! | E15: ='Belgium (quarter)'!C44 -> #REF! | F15: ='Belgium (quarter)'!C50 -> #REF!
B17: Germany | D17: NPS | E17: Rank | F17: n
B18: ING | D18: ='Germany (quarter)'!C6 -> #REF! | E18: ='Germany (quarter)'!C57 -> #REF! | F18: ='Germany (quarter)'!C65 -> #REF!
B19: Commerzbank | D19: ='Germany (quarter)'!C14 -> #REF! | E19: ='Germany (quarter)'!C58 -> #REF! | F19: ='Germany (quarter)'!C66 -> #REF!
B20: DKB | D20: ='Germany (quarter)'!C21 -> #REF! | E20: ='Germany (quarter)'!C59 -> #REF! | F20: ='Germany (quarter)'!C67 -> #REF!
B21: Postbank | D21: ='Germany (quarter)'!C28 -> #REF! | E21: ='Germany (quarter)'!C60 -> #REF! | F21: ='Germany (quarter)'!C68 -> #REF!
B22: Sparkasse | D22: ='Germany (quarter)'!C35 -> #REF! | E22: ='Germany (quarter)'!C61 -> #REF! | F22: ='Germany (quarter)'!C69 -> #REF!
B23: VR-Banken | D23: ='Germany (quarter)'!C42 -> #REF! | E23: ='Germany (quarter)'!C62 -> #REF! | F23: ='Germany (quarter)'!C70 -> #REF!
B25: Italy | D25: NPS | E25: Rank | F25: n
B26: ING | D26: ='Italy (quarter)'!C6 -> #REF! | E26: ='Italy (quarter)'!C57 -> #REF! | F26: ='Italy (quarter)'!C65 -> #REF!
B27: Banca Mediolanum | D27: ='Italy (quarter)'!C14 -> #REF! | E27: ='Italy (quarter)'!C58 -> #REF! | F27: ='Italy (quarter)'!C66 -> #REF!
B28: BancoPosta | D28: ='Italy (quarter)'!C21 -> #REF! | E28: ='Italy (quarter)'!C59 -> #REF! | F28: ='Italy (quarter)'!C67 -> #REF!
B29: Fineco | D29: ='Italy (quarter)'!C28 -> #REF! | E29: ='Italy (quarter)'!C60 -> #REF! | F29: ='Italy (quarter)'!C68 -> #REF!
B30: Intesa Sanpaolo | D30: ='Italy (quarter)'!C35 -> #REF! | E30: ='Italy (quarter)'!C61 -> #REF! | F30: ='Italy (quarter)'!C69 -> #REF!
B31: Unicredit | D31: ='Italy (quarter)'!C42 -> #REF! | E31: ='Italy (quarter)'!C62 -> #REF! | F31: ='Italy (quarter)'!C70 -> #REF!
B33: Luxembourg | D33: NPS | E33: Rank | F33: n
B34: ING | D34: =#REF! -> #REF! | E34: =#REF! -> #REF! | F34: =#REF! -> #REF!
B35: Banque et Caisse d’Epargne de l’Etat / Spuerkeess / BCEE | D35: =#REF! -> #REF! | E35: =#REF! -> #REF! | F35: =#REF! -> #REF!
B36: Banque International a Luxembourg | D36: =#REF! -> #REF! | E36: =#REF! -> #REF! | F36: =#REF! -> #REF!
B37: BGL BNP Paribas | D37: =#REF! -> #REF! | E37: =#REF! -> #REF! | F37: =#REF! -> #REF!
B38: Post | D38: =#REF! -> #REF! | E38: =#REF! -> #REF! | F38: =#REF! -> #REF!
B39: Raiffeisen | D39: =#REF! -> #REF! | E39: =#REF! -> #REF! | F39: =#REF! -> #REF!
B41: The Netherlands | D41: NPS | E41: Rank | F41: n
B42: ING | D42: ='Netherlands (quarter)'!C35 -> #REF! | E42: ='Netherlands (quarter)'!C41 -> #REF! | F42: ='Netherlands (quarter)'!C47 -> #REF!
B43: ABN AMRO | D43: ='Netherlands (quarter)'!C36 -> #REF! | E43: ='Netherlands (quarter)'!C42 -> #REF! | F43: ='Netherlands (quarter)'!C48 -> #REF!
B44: Rabobank | D44: ='Netherlands (quarter)'!C37 -> #REF! | E44: ='Netherlands (quarter)'!C43 -> #REF! | F44: ='Netherlands (quarter)'!C49 -> #REF!
B45: SNS bank | D45: ='Netherlands (quarter)'!#REF! -> #REF! | E45: ='Netherlands (quarter)'!#REF! -> #REF! | F45: ='Netherlands (quarter)'!#REF! -> #REF!
B46: ASN bank | D46: ='Netherlands (quarter)'!C38 -> #REF! | E46: ='Netherlands (quarter)'!C44 -> #REF! | F46: ='Netherlands (quarter)'!C50 -> #REF!
B48: Poland | D48: NPS | E48: Rank | F48: n
...

Sheet Countries overview (monthly)
B2: Source: Global NPS tracking / Toluna | C2: January - 2026 | F2: February - 2026 | I2: March - 2026
B4: Australia | C4: NPS | D4: Rank | E4: n | F4: NPS | G4: Rank | H4: n | I4: NPS | J4: Rank | K4: n
B5: Commonwealth Bank | C5: ='Australia (Month)'!C42 -> 43.719344 | D5: =RANK(C5,$C$5:$C$22,0) -> 3 | E5: ='Australia (Month)'!C57 -> 331 | F5: ='Australia (Month)'!D42 -> 42.72414 | G5: =RANK(F5,$F$5:$F$22,0) -> 2 | H5: ='Australia (Month)'!D57 -> 401 | I5: ='Australia (Month)'!E42 -> 43.929886 | J5: =RANK(I5,$I$5:$I$22,0) -> 1 | K5: ='Australia (Month)'!E57 -> 391
B6: ANZ | C6: ='Australia (Month)'!C24 -> 44.621825 | D6: =RANK(C6,$C$5:$C$22,0) -> 2 | E6: ='Australia (Month)'!C39 -> 124 | F6: ='Australia (Month)'!D24 -> 42.488528 | G6: =RANK(F6,$F$5:$F$22,0) -> 3 | H6: ='Australia (Month)'!D39 -> 157 | I6: ='Australia (Month)'!E24 -> 38.373295 | J6: =RANK(I6,$I$5:$I$22,0) -> 2 | K6: ='Australia (Month)'!E39 -> 149
B7: Westpac | C7: ='Australia (Month)'!C78 -> 50.112199 | D7: =RANK(C7,$C$5:$C$22,0) -> 1 | E7: ='Australia (Month)'!C93 -> 113 | F7: ='Australia (Month)'!D78 -> 44.665324 | G7: =RANK(F7,$F$5:$F$22,0) -> 1 | H7: ='Australia (Month)'!D93 -> 141 | I7: ='Australia (Month)'!E78 -> 37.664561 | J7: =RANK(I7,$I$5:$I$22,0) -> 3 | K7: ='Australia (Month)'!E93 -> 137
B8: NAB (National Australia Bank) | C8: ='Australia (Month)'!C60 -> 31.411084 | D8: =RANK(C8,$C$5:$C$22,0) -> 4 | E8: ='Australia (Month)'!C75 -> 104 | F8: ='Australia (Month)'!D60 -> 29.606533 | G8: =RANK(F8,$F$5:$F$22,0) -> 4 | H8: ='Australia (Month)'!D75 -> 120 | I8: ='Australia (Month)'!E60 -> 29.562953 | J8: =RANK(I8,$I$5:$I$22,0) -> 4 | K8: ='Australia (Month)'!E75 -> 117
B9: ING | C9: ='Australia (Month)'!C6 -> 17.404865 | D9: =RANK(C9,$C$5:$C$22,0) -> 5 | E9: ='Australia (Month)'!C21 -> 42 | F9: ='Australia (Month)'!D6 -> 20.861557 | G9: =RANK(F9,$F$5:$F$22,0) -> 5 | H9: ='Australia (Month)'!D21 -> 53 | I9: ='Australia (Month)'!E6 -> 13.983207 | J9: =RANK(I9,$I$5:$I$22,0) -> 5 | K9: ='Australia (Month)'!E21 -> 48
B10: Bank of Australia | C10: ='Australia (Month)'!C96 -> Low N | D10: Low N | E10: ='Australia (Month)'!C111 -> 39 | F10: ='Australia (Month)'!D96 -> Low N | G10: Low N | H10: ='Australia (Month)'!D111 -> 53 | I10: ='Australia (Month)'!E96 -> Low N | J10: Low N | K10: ='Australia (Month)'!E111 -> 52
B11: Bankwest | C11: ='Australia (Month)'!C114 -> Low N | D11: Low N | E11: ='Australia (Month)'!C129 -> 19 | F11: ='Australia (Month)'!D114 -> Low N | G11: Low N | H11: ='Australia (Month)'!D129 -> 25 | I11: ='Australia (Month)'!E114 -> Low N | J11: Low N | K11: ='Australia (Month)'!E129 -> 25
B12: Bendigo Bank | C12: ='Australia (Month)'!C132 -> Low N | D12: Low N | E12: ='Australia (Month)'!C147 -> 25 | F12: ='Australia (Month)'!D132 -> Low N | G12: Low N | H12: ='Australia (Month)'!D147 -> 31 | I12: ='Australia (Month)'!E132 -> Low N | J12: Low N | K12: ='Australia (Month)'!E147 -> 26
B13: BoQ | C13: ='Australia (Month)'!C150 -> Low N | D13: Low N | E13: ='Australia (Month)'!C165 -> 13 | F13: ='Australia (Month)'!D150 -> Low N | G13: Low N | H13: ='Australia (Month)'!D165 -> 14 | I13: ='Australia (Month)'!E150 -> Low N | J13: Low N | K13: ='Australia (Month)'!E165 -> 13
B14: Citibank | C14: ='Australia (Month)'!C168 -> Low N | D14: Low N | E14: ='Australia (Month)'!C183 -> 34 | F14: ='Australia (Month)'!D168 -> Low N | G14: Low N | H14: ='Australia (Month)'!D183 -> 43 | I14: ='Australia (Month)'!E168 -> Low N | J14: Low N | K14: ='Australia (Month)'!E183 -> 40
B15: HSBC | C15: ='Australia (Month)'!C186 -> Low N | D15: Low N | E15: ='Australia (Month)'!C201 -> 53 | F15: ='Australia (Month)'!D186 -> Low N | G15: Low N | H15: ='Australia (Month)'!D201 -> 67 | I15: ='Australia (Month)'!E186 -> Low N | J15: Low N | K15: ='Australia (Month)'!E201 -> 49
B16: Macquarie Bank | C16: ='Australia (Month)'!C204 -> Low N | D16: Low N | E16: ='Australia (Month)'!C219 -> 55 | F16: ='Australia (Month)'!D204 -> Low N | G16: Low N | H16: ='Australia (Month)'!D219 -> 68 | I16: ='Australia (Month)'!E204 -> Low N | J16: Low N | K16: ='Australia (Month)'!E219 -> 65
B17: MEBank (Members Equity) | C17: ='Australia (Month)'!C222 -> Low N | D17: Low N | E17: ='Australia (Month)'!C237 -> 13 | F17: ='Australia (Month)'!D222 -> Low N | G17: Low N | H17: ='Australia (Month)'!D237 -> 16 | I17: ='Australia (Month)'!E222 -> Low N | J17: Low N | K17: ='Australia (Month)'!E237 -> 15
B18: St George | C18: ='Australia (Month)'!C240 -> Low N | D18: Low N | E18: ='Australia (Month)'!C255 -> 34 | F18: ='Australia (Month)'!D240 -> Low N | G18: Low N | H18: ='Australia (Month)'!D255 -> 39 | I18: ='Australia (Month)'!E240 -> Low N | J18: Low N | K18: ='Australia (Month)'!E255 -> 34
B19: Suncorp | C19: ='Australia (Month)'!C258 -> Low N | D19: Low N | E19: ='Australia (Month)'!C273 -> 32 | F19: ='Australia (Month)'!D258 -> Low N | G19: Low N | H19: ='Australia (Month)'!D273 -> 39 | I19: ='Australia (Month)'!E258 -> Low N | J19: Low N | K19: ='Australia (Month)'!E273 -> 33
B20: Ubank | C20: ='Australia (Month)'!C276 -> Low N | D20: Low N | E20: ='Australia (Month)'!C291 -> 14 | F20: ='Australia (Month)'!D276 -> Low N | G20: Low N | H20: ='Australia (Month)'!D291 -> 15 | I20: ='Australia (Month)'!E276 -> Low N | J20: Low N | K20: ='Australia (Month)'!E291 -> 19
B21: Revolut | C21: ='Australia (Month)'!C294 -> Low N | D21: Low N | E21: ='Australia (Month)'!C309 -> 30 | F21: ='Australia (Month)'!D294 -> Low N | G21: Low N | H21: ='Australia (Month)'!D309 -> 40 | I21: ='Australia (Month)'!E294 -> Low N | J21: Low N | K21: ='Australia (Month)'!E309 -> 42
B22: Up bank | C22: ='Australia (Month)'!C312 -> Low N | D22: Low N | E22: ='Australia (Month)'!C327 -> 13 | F22: ='Australia (Month)'!D312 -> Low N | G22: Low N | H22: ='Australia (Month)'!D327 -> 14 | I22: ='Australia (Month)'!E312 -> Low N | J22: Low N | K22: ='Australia (Month)'!E327 -> 14
B24: Belgium | C24: NPS | D24: Rank | E24: n | F24: NPS | G24: Rank | H24: n | I24: NPS | J24: Rank | K24: n
B25: Revolut | C25: ='Belgium (Month)'!C204 -> Low N | D25: Low N | E25: ='Belgium (Month)'!C219 -> 84 | F25: ='Belgium (Month)'!D204 -> 27.184115 | G25: =RANK(F25,$F$25:$F$40,0) -> 1 | H25: ='Belgium (Month)'!D219 -> 108 | I25: ='Belgium (Month)'!E204 -> 29.562701 | J25: =RANK(I25,$I$25:$I$40,0) -> 1 | K25: ='Belgium (Month)'!E219 -> 115
B26: Keytrade Bank | C26: ='Belgium (Month)'!C186 -> 19.826581 | D26: =RANK(C26,$C$25:$C$40,0) -> 1 | E26: ='Belgium (Month)'!C201 -> 131 | F26: ='Belgium (Month)'!D186 -> 20.382306 | G26: =RANK(F26,$F$25:$F$40,0) -> 2 | H26: ='Belgium (Month)'!D201 -> 152 | I26: ='Belgium (Month)'!E186 -> 25.261652 | J26: =RANK(I26,$I$25:$I$40,0) -> 2 | K26: ='Belgium (Month)'!E201 -> 148
B27: Argenta | C27: ='Belgium (Month)'!C78 -> 8.6148019 | D27: =RANK(C27,$C$25:$C$40,0) -> 7 | E27: ='Belgium (Month)'!C93 -> 315 | F27: ='Belgium (Month)'!D78 -> 10.919803 | G27: =RANK(F27,$F$25:$F$40,0) -> 5 | H27: ='Belgium (Month)'!D93 -> 378 | I27: ='Belgium (Month)'!E78 -> 16.834355 | J27: =RANK(I27,$I$25:$I$40,0) -> 3 | K27: ='Belgium (Month)'!E93 -> 366
B28: BNP Paribas Fortis | C28: ='Belgium (Month)'!C42 -> 13.642026 | D28: =RANK(C28,$C$25:$C$40,0) -> 4 | E28: ='Belgium (Month)'!C57 -> 455 | F28: ='Belgium (Month)'!D42 -> 10.35423 | G28: =RANK(F28,$F$25:$F$40,0) -> 7 | H28: ='Belgium (Month)'!D57 -> 546 | I28: ='Belgium (Month)'!E42 -> 14.946107 | J28: =RANK(I28,$I$25:$I$40,0) -> 4 | K28: ='Belgium (Month)'!E57 -> 532
B29: KBC/CBC | C29: ='Belgium (Month)'!C60 -> 13.918667 | D29: =RANK(C29,$C$25:$C$40,0) -> 3 | E29: ='Belgium (Month)'!C75 -> 420 | F29: ='Belgium (Month)'!D60 -> 14.392067 | G29: =RANK(F29,$F$25:$F$40,0) -> 3 | H29: ='Belgium (Month)'!D75 -> 508 | I29: ='Belgium (Month)'!E60 -> 13.328339 | J29: =RANK(I29,$I$25:$I$40,0) -> 5 | K29: ='Belgium (Month)'!E75 -> 496
B30: Belfius | C30: ='Belgium (Month)'!C24 -> 14.414706 | D30: =RANK(C30,$C$25:$C$40,0) -> 2 | E30: ='Belgium (Month)'!C39 -> 451 | F30: ='Belgium (Month)'!D24 -> 12.472744 | G30: =RANK(F30,$F$25:$F$40,0) -> 4 | H30: ='Belgium (Month)'!D39 -> 544 | I30: ='Belgium (Month)'!E24 -> 12.901733 | J30: =RANK(I30,$I$25:$I$40,0) -> 6 | K30: ='Belgium (Month)'!E39 -> 530
B31: Crelan | C31: ='Belgium (Month)'!C114 -> 9.2041353 | D31: =RANK(C31,$C$25:$C$40,0) -> 6 | E31: ='Belgium (Month)'!C129 -> 150 | F31: ='Belgium (Month)'!D114 -> 9.5530681 | G31: =RANK(F31,$F$25:$F$40,0) -> 8 | H31: ='Belgium (Month)'!D129 -> 180 | I31: ='Belgium (Month)'!E114 -> 8.8219655 | J31: =RANK(I31,$I$25:$I$40,0) -> 7 | K31: ='Belgium (Month)'!E129 -> 192
B32: ING | C32: ='Belgium (Month)'!C6 -> 11.545893 | D32: =RANK(C32,$C$25:$C$40,0) -> 5 | E32: ='Belgium (Month)'!C21 -> 219 | F32: ='Belgium (Month)'!D6 -> 10.763037 | G32: =RANK(F32,$F$25:$F$40,0) -> 6 | H32: ='Belgium (Month)'!D21 -> 268 | I32: ='Belgium (Month)'!E6 -> 8.5654767 | J32: =RANK(I32,$I$25:$I$40,0) -> 8 | K32: ='Belgium (Month)'!E21 -> 275
B33: DEGIRO | C33: ='Belgium (Month)'!C258 -> 2.4549292 | D33: =RANK(C33,$C$25:$C$40,0) -> 8 | E33: ='Belgium (Month)'!C273 -> 153 | F33: ='Belgium (Month)'!D258 -> 6.4150402 | G33: =RANK(F33,$F$25:$F$40,0) -> 9 | H33: ='Belgium (Month)'!D273 -> 196 | I33: ='Belgium (Month)'!E258 -> 7.9080325 | J33: =RANK(I33,$I$25:$I$40,0) -> 9 | K33: ='Belgium (Month)'!E273 -> 206
B34: Bolero | C34: ='Belgium (Month)'!C222 -> 1.3757745 | D34: =RANK(C34,$C$25:$C$40,0) -> 9 | E34: ='Belgium (Month)'!C237 -> 308 | F34: ='Belgium (Month)'!D222 -> 0.98354694 | G34: =RANK(F34,$F$25:$F$40,0) -> 10 | H34: ='Belgium (Month)'!D237 -> 402 | I34: ='Belgium (Month)'!E222 -> 2.0424661 | J34: =RANK(I34,$I$25:$I$40,0) -> 10 | K34: ='Belgium (Month)'!E237 -> 419
B35: Trade republic | C35: ='Belgium (Month)'!C276 -> 0.67753147 | D35: =RANK(C35,$C$25:$C$40,0) -> 10 | E35: ='Belgium (Month)'!C291 -> 162 | F35: ='Belgium (Month)'!D276 -> -2.2451811 | G35: =RANK(F35,$F$25:$F$40,0) -> 12 | H35: ='Belgium (Month)'!D291 -> 221 | I35: ='Belgium (Month)'!E276 -> 0.54808895 | J35: =RANK(I35,$I$25:$I$40,0) -> 11 | K35: ='Belgium (Month)'!E291 -> 233
B36: eToro | C36: ='Belgium (Month)'!C240 -> 0.0091775789 | D36: =RANK(C36,$C$25:$C$40,0) -> 11 | E36: ='Belgium (Month)'!C255 -> 148 | F36: ='Belgium (Month)'!D240 -> -1.0766291 | G36: =RANK(F36,$F$25:$F$40,0) -> 11 | H36: ='Belgium (Month)'!D255 -> 191 | I36: ='Belgium (Month)'!E240 -> -0.54086286 | J36: =RANK(I36,$I$25:$I$40,0) -> 12 | K36: ='Belgium (Month)'!E255 -> 196
B37: Beobank | C37: ='Belgium (Month)'!C96 -> Low N | D37: Low N | E37: ='Belgium (Month)'!C111 -> 55 | F37: ='Belgium (Month)'!D96 -> Low N | G37: Low N | H37: ='Belgium (Month)'!D111 -> 64 | I37: ='Belgium (Month)'!E96 -> Low N | J37: Low N | K37: ='Belgium (Month)'!E111 -> 67
B38: Deutsche Bank | C38: ='Belgium (Month)'!C132 -> Low N | D38: Low N | E38: ='Belgium (Month)'!C147 -> 64 | F38: ='Belgium (Month)'!D132 -> Low N | G38: Low N | H38: ='Belgium (Month)'!D147 -> 72 | I38: ='Belgium (Month)'!E132 -> Low N | J38: Low N | K38: ='Belgium (Month)'!E147 -> 68
B39: Fintro | C39: ='Belgium (Month)'!C150 -> Low N | D39: Low N | E39: ='Belgium (Month)'!C165 -> 47 | F39: ='Belgium (Month)'!D150 -> Low N | G39: Low N | H39: ='Belgium (Month)'!D165 -> 57 | I39: ='Belgium (Month)'!E150 -> Low N | J39: Low N | K39: ='Belgium (Month)'!E165 -> 53
B40: Hello Bank | C40: ='Belgium (Month)'!C168 -> Low N | D40: Low N | E40: ='Belgium (Month)'!C183 -> 26 | F40: ='Belgium (Month)'!D168 -> Low N | G40: Low N | H40: ='Belgium (Month)'!D183 -> 33 | I40: ='Belgium (Month)'!E168 -> Low N | J40: Low N | K40: ='Belgium (Month)'!E183 -> 36
B42: Germany | C42: NPS | D42: Rank | E42: n | F42: NPS | G42: Rank | H42: n | I42: NPS | J42: Rank | K42: n
B43: Revolut | C43: ='Germany (Month)'!C222 -> Low N | D43: Low N | E43: ='Germany (Month)'!C237 -> 92 | F43: ='Germany (Month)'!D222 -> 56.272619 | G43: =RANK(F43,$F$43:$F$58,0) -> 1 | H43: ='Germany (Month)'!D237 -> 116 | I43: ='Germany (Month)'!E222 -> 50.896528 | J43: =RANK(I43,$I$43:$I$58,0) -> 1 | K43: ='Germany (Month)'!E237 -> 106
B44: Trade Republic | C44: ='Germany (Month)'!C240 -> 46.022213 | D44: =RANK(C44,$C$43:$C$58,0) -> 1 | E44: ='Germany (Month)'!C255 -> 287 | F44: ='Germany (Month)'!D240 -> 46.07108 | G44: =RANK(F44,$F$43:$F$58,0) -> 2 | H44: ='Germany (Month)'!D255 -> 337 | I44: ='Germany (Month)'!E240 -> 46.852005 | J44: =RANK(I44,$I$43:$I$58,0) -> 2 | K44: ='Germany (Month)'!E255 -> 343
...

Sheet Australia (quarter)
B2: Source: Global NPS tracking / Toluna | C2: Q4 - 2025
B4: Rolling NPS Data - Total
B5: ING
B6: NPS - ING (%) | C6: ='Australia (Month)'!#REF! -> #REF!
B7: Rank - ING | C7: =C49 -> #REF!
B8: Promoter - ING (%) | C8: ='Australia (Month)'!#REF! -> #REF!
B9: Passive - ING (%) | C9: ='Australia (Month)'!#REF! -> #REF!
B10: Detractor - ING (%) | C10: ='Australia (Month)'!#REF! -> #REF!
B12: Key competitors
B13: ANZ
B14: NPS - ANZ (%) | C14: ='Australia (Month)'!#REF! -> #REF!
B15: Rank - ANZ | C15: =C50 -> #REF!
B16: Promoter - ANZ (%) | C16: ='Australia (Month)'!#REF! -> #REF!
B17: Passive - ANZ (%) | C17: ='Australia (Month)'!#REF! -> #REF!
B18: Detractor - ANZ (%) | C18: ='Australia (Month)'!#REF! -> #REF!
B20: Commonwealth Bank
B21: NPS - Commonwealth Bank (%) | C21: ='Australia (Month)'!#REF! -> #REF!
B22: Rank - Commonwealth Bank | C22: =C51 -> #REF!
B23: Promoter - Commonwealth Bank (%) | C23: ='Australia (Month)'!#REF! -> #REF!
B24: Passive - Commonwealth Bank (%) | C24: ='Australia (Month)'!#REF! -> #REF!
B25: Detractor - Commonwealth Bank (%) | C25: ='Australia (Month)'!#REF! -> #REF!
B27: NAB - National Australia Bank
B28: NPS - NAB (%) | C28: ='Australia (Month)'!#REF! -> #REF!
B29: Rank - NAB | C29: =C52 -> #REF!
B30: Promoter - NAB (%) | C30: ='Australia (Month)'!#REF! -> #REF!
B31: Passive - NAB (%) | C31: ='Australia (Month)'!#REF! -> #REF!
B32: Detractor - NAB (%) | C32: ='Australia (Month)'!#REF! -> #REF!
B34: Westpac
B35: NPS - Westpac (%) | C35: ='Australia (Month)'!#REF! -> #REF!
B36: Rank - Westpac | C36: =C53 -> #REF!
B37: Promoter - Westpac (%) | C37: ='Australia (Month)'!#REF! -> #REF!
B38: Passive - Westpac (%) | C38: ='Australia (Month)'!#REF! -> #REF!
B39: Detractor - Westpac (%) | C39: ='Australia (Month)'!#REF! -> #REF!
B41: NPS - ING & Key competitors (For ranking)
B42: ING | C42: =C6 -> #REF!
B43: ANZ | C43: =C14 -> #REF!
B44: Commonwealth Bank | C44: =C21 -> #REF!
B45: NAB (National Australia Bank) | C45: =C28 -> #REF!
B46: Westpac | C46: =C35 -> #REF!
B48: Ranking formule
...

Sheet Australia (Month)
B2: Source: Global NPS tracking / Toluna | C2: January - 2026 (6 months rolling) | D2: February - 2026 (6 months rolling) | E2: March - 2026 (6 months rolling)
B4: NPS total
B5: ING | C5: NPS | D5: NPS | E5: NPS
C6: ='Australia Crunch Output'!G21 -> 17.404865 | D6: ='Australia Crunch Output'!H21 -> 20.861557 | E6: ='Australia Crunch Output'!I21 -> 13.983207
B7: Promoter | C7: ='Australia Crunch Output'!G7 -> 0.39838158 | D7: ='Australia Crunch Output'!H7 -> 0.39646689 | E7: ='Australia Crunch Output'!I7 -> 0.35230341
B8: Passive | C8: ='Australia Crunch Output'!G8 -> 0.37728548 | D8: ='Australia Crunch Output'!H8 -> 0.41568179 | E8: ='Australia Crunch Output'!I8 -> 0.43522525
B9: Detractor | C9: ='Australia Crunch Output'!G9 -> 0.22433293 | D9: ='Australia Crunch Output'!H9 -> 0.18785132 | E9: ='Australia Crunch Output'!I9 -> 0.21247134
B10: Extremely likely | C10: ='Australia Crunch Output'!G10 -> 0.25217444 | D10: ='Australia Crunch Output'!H10 -> 0.26119081 | E10: ='Australia Crunch Output'!I10 -> 0.21694215
B11: 9 | C11: ='Australia Crunch Output'!G11 -> 0.14620714 | D11: ='Australia Crunch Output'!H11 -> 0.13527608 | E11: ='Australia Crunch Output'!I11 -> 0.13536126
B12: 8 | C12: ='Australia Crunch Output'!G12 -> 0.26618879 | D12: ='Australia Crunch Output'!H12 -> 0.28948345 | E12: ='Australia Crunch Output'!I12 -> 0.29309967
B13: 7 | C13: ='Australia Crunch Output'!G13 -> 0.1110967 | D13: ='Australia Crunch Output'!H13 -> 0.12619834 | E13: ='Australia Crunch Output'!I13 -> 0.14212558
B14: 6 | C14: ='Australia Crunch Output'!G14 -> 0.17702314 | D14: ='Australia Crunch Output'!H14 -> 0.15027529 | E14: ='Australia Crunch Output'!I14 -> 0.17180229
B15: 5 | C15: ='Australia Crunch Output'!G15 -> 0.023547444 | D15: ='Australia Crunch Output'!H15 -> 0.01870267 | E15: ='Australia Crunch Output'!I15 -> 0.020242155
B16: 4 | C16: ='Australia Crunch Output'!G16 -> 0.023762355 | D16: ='Australia Crunch Output'!H16 -> 0.018873364 | E16: ='Australia Crunch Output'!I16 -> 0.0204269
B17: 3 | C17: ='Australia Crunch Output'!G17 -> 0 | D17: ='Australia Crunch Output'!H17 -> 0 | E17: ='Australia Crunch Output'!I17 -> 0
B18: 2 | C18: ='Australia Crunch Output'!G18 -> 0 | D18: ='Australia Crunch Output'!H18 -> 0 | E18: ='Australia Crunch Output'!I18 -> 0
B19: 1 | C19: ='Australia Crunch Output'!G19 -> 0 | D19: ='Australia Crunch Output'!H19 -> 0 | E19: ='Australia Crunch Output'!I19 -> 0
B20: Extremely Unlikely | C20: ='Australia Crunch Output'!G20 -> 0 | D20: ='Australia Crunch Output'!H20 -> 0 | E20: ='Australia Crunch Output'!I20 -> 0
B21: n | C21: ='Australia Crunch Output'!G6 -> 42 | D21: ='Australia Crunch Output'!H6 -> 53 | E21: ='Australia Crunch Output'!I6 -> 48
B23: ANZ | C23: NPS | D23: NPS | E23: NPS
C24: ='Australia Crunch Output'!G40 -> 44.621825 | D24: ='Australia Crunch Output'!H40 -> 42.488528 | E24: ='Australia Crunch Output'!I40 -> 38.373295
B25: Promoter | C25: ='Australia Crunch Output'!G26 -> 0.52486817 | D25: ='Australia Crunch Output'!H26 -> 0.52061667 | E25: ='Australia Crunch Output'!I26 -> 0.50065198
B26: Passive | C26: ='Australia Crunch Output'!G27 -> 0.3964819 | D26: ='Australia Crunch Output'!H27 -> 0.38365194 | E26: ='Australia Crunch Output'!I27 -> 0.38242899
B27: Detractor | C27: ='Australia Crunch Output'!G28 -> 0.078649925 | D27: ='Australia Crunch Output'!H28 -> 0.095731393 | E27: ='Australia Crunch Output'!I28 -> 0.11691903
B28: Extremely likely | C28: ='Australia Crunch Output'!G29 -> 0.2618003 | D28: ='Australia Crunch Output'!H29 -> 0.26383604 | E28: ='Australia Crunch Output'!I29 -> 0.25196124
B29: 9 | C29: ='Australia Crunch Output'!G30 -> 0.26306787 | D29: ='Australia Crunch Output'!H30 -> 0.25678063 | E29: ='Australia Crunch Output'!I30 -> 0.24869074
B30: 8 | C30: ='Australia Crunch Output'!G31 -> 0.27788914 | D30: ='Australia Crunch Output'!H31 -> 0.28287399 | E30: ='Australia Crunch Output'!I31 -> 0.27779568
B31: 7 | C31: ='Australia Crunch Output'!G32 -> 0.11859276 | D31: ='Australia Crunch Output'!H32 -> 0.10077795 | E31: ='Australia Crunch Output'!I32 -> 0.10463331
B32: 6 | C32: ='Australia Crunch Output'!G33 -> 0.041566955 | D32: ='Australia Crunch Output'!H33 -> 0.033017907 | E32: ='Australia Crunch Output'!I33 -> 0.043605856
B33: 5 | C33: ='Australia Crunch Output'!G34 -> 0.037082971 | D33: ='Australia Crunch Output'!H34 -> 0.056081123 | E33: ='Australia Crunch Output'!I34 -> 0.054296797
B34: 4 | C34: ='Australia Crunch Output'!G35 -> 0 | D34: ='Australia Crunch Output'!H35 -> 0 | E34: ='Australia Crunch Output'!I35 -> 0.0056585511
B35: 3 | C35: ='Australia Crunch Output'!G36 -> 0 | D35: ='Australia Crunch Output'!H36 -> 0 | E35: ='Australia Crunch Output'!I36 -> 0
B36: 2 | C36: ='Australia Crunch Output'!G37 -> 0 | D36: ='Australia Crunch Output'!H37 -> 0.0066323623 | E36: ='Australia Crunch Output'!I37 -> 0.0068913057
B37: 1 | C37: ='Australia Crunch Output'!G38 -> 0 | D37: ='Australia Crunch Output'!H38 -> 0 | E37: ='Australia Crunch Output'!I38 -> 0.0064665179
B38: Extremely Unlikely | C38: ='Australia Crunch Output'!G39 -> 0 | D38: ='Australia Crunch Output'!H39 -> 0 | E38: ='Australia Crunch Output'!I39 -> 0
B39: n | C39: ='Australia Crunch Output'!G25 -> 124 | D39: ='Australia Crunch Output'!H25 -> 157 | E39: ='Australia Crunch Output'!I25 -> 149
B41: Commonwealth Bank | C41: NPS | D41: NPS | E41: NPS
C42: ='Australia Crunch Output'!G59 -> 43.719344 | D42: ='Australia Crunch Output'!H59 -> 42.72414 | E42: ='Australia Crunch Output'!I59 -> 43.929886
B43: Promoter | C43: ='Australia Crunch Output'!G45 -> 0.5501922 | D43: ='Australia Crunch Output'!H45 -> 0.54792716 | E43: ='Australia Crunch Output'!I45 -> 0.55717797
B44: Passive | C44: ='Australia Crunch Output'!G46 -> 0.33680904 | D44: ='Australia Crunch Output'!H46 -> 0.33138707 | E44: ='Australia Crunch Output'!I46 -> 0.32494292
...

Sheet Australia Crunch  Output
A1: P97511: ING BAM: Australia
A2: Investment NPS
A3: Based on your knowledge and experience with the investment services offered by the brand(s) below, how likely is it that you would recommend their investment services to a friend, family member or colleague?
A5: Investment NPS: ING | B5: All | C5: Apr 2025 - Sep 2025 | D5: May 2025 - Oct 2025 | E5: June 2025 - Nov 2025 | F5: July 2025 - Dec 2025 | G5: August 2025 - Jan 2026 | H5: Sep 2025 - Feb 2026 | I5: Oct 2025 - Mar 2026
A6: Unweighted N | B6: 34 | C6: 12 | D6: 16 | E6: 26 | F6: 34 | G6: 42 | H6: 53 | I6: 48
A7: Promoter | B7: 0.43309219 | C7: 0.60029294 | D7: 0.5751047 | E7: 0.49578486 | F7: 0.43309219 | G7: 0.39838158 | H7: 0.39646689 | I7: 0.35230341
A8: Passive | B8: 0.34740457 | C8: 0.3133977 | D8: 0.2352106 | E8: 0.34543323 | F8: 0.34740457 | G8: 0.37728548 | H8: 0.41568179 | I8: 0.43522525
A9: Detractor | B9: 0.21950324 | C9: 0.086309354 | D9: 0.1896847 | E9: 0.1587819 | F9: 0.21950324 | G9: 0.22433293 | H9: 0.18785132 | I9: 0.21247134
A10: Extremely Likely | B10: 0.28166927 | C10: 0.47703713 | D10: 0.42845271 | E10: 0.28946752 | F10: 0.28166927 | G10: 0.25217444 | H10: 0.26119081 | I10: 0.21694215
A11: 9 | B11: 0.15142292 | C11: 0.12325582 | D11: 0.14665199 | E11: 0.20631734 | F11: 0.15142292 | G11: 0.14620714 | H11: 0.13527608 | I11: 0.13536126
A12: 8 | B12: 0.20872222 | C12: 0.17568308 | D12: 0.1318533 | E12: 0.20062037 | F12: 0.20872222 | G12: 0.26618879 | H12: 0.28948345 | I12: 0.29309967
A13: 7 | B13: 0.13868235 | C13: 0.13771462 | D13: 0.10335729 | E13: 0.14481286 | F13: 0.13868235 | G13: 0.1110967 | H13: 0.12619834 | I13: 0.14212558
A14: 6 | B14: 0.19010889 | C14: 0.086309354 | D14: 0.1896847 | E14: 0.1587819 | F14: 0.19010889 | G14: 0.17702314 | H14: 0.15027529 | I14: 0.17180229
A15: 5 | B15: 0.029394347 | C15: 0 | D15: 0 | E15: 0 | F15: 0.029394347 | G15: 0.023547444 | H15: 0.01870267 | I15: 0.020242155
A16: 4 | B16: 0 | C16: 0 | D16: 0 | E16: 0 | F16: 0 | G16: 0.023762355 | H16: 0.018873364 | I16: 0.0204269
A17: 3 | B17: 0 | C17: 0 | D17: 0 | E17: 0 | F17: 0 | G17: 0 | H17: 0 | I17: 0
... A20: Extremely Unlikely | B20: 0 | C20: 0 | D20: 0 | E20: 0 | F20: 0 | G20: 0 | H20: 0 | I20: 0
A21: Mean | B21: =(B7-B9)*100 -> 21.358895 | C21: =(C7-C9)*100 -> 51.398359 | D21: =(D7-D9)*100 -> 38.542 | E21: =(E7-E9)*100 -> 33.700296 | F21: =(F7-F9)*100 -> 21.358895 | G21: 17.404865 | H21: 20.861557 | I21: 13.983207
A24: Investment NPS: ANZ | B24: All | C24: Apr 2025 - Sep 2025 | D24: May 2025 - Oct 2025 | E24: June 2025 - Nov 2025 | F24: July 2025 - Dec 2025 | G24: August 2025 - Jan 2026 | H24: Sep 2025 - Feb 2026 | I24: Oct 2025 - Mar 2026
A25: Unweighted N | B25: 102 | C25: 27 | D25: 48 | E25: 76 | F25: 102 | G25: 124 | H25: 157 | I25: 149
A26: Promoter | B26: 0.51344409 | C26: 0.63005152 | D26: 0.59530687 | E26: 0.5431767 | F26: 0.51344409 | G26: 0.52486817 | H26: 0.52061667 | I26: 0.50065198
A27: Passive | B27: 0.4028706 | C27: 0.28389129 | D27: 0.28942979 | E27: 0.36181018 | F27: 0.4028706 | G27: 0.3964819 | H27: 0.38365194 | I27: 0.38242899
A28: Detractor | B28: 0.083685316 | C28: 0.086057184 | D28: 0.11526334 | E28: 0.095013117 | F28: 0.083685316 | G28: 0.078649925 | H28: 0.095731393 | I28: 0.11691903
A29: Extremely Likely | B29: 0.24659197 | C29: 0.33565522 | D29: 0.26720384 | E29: 0.25172552 | F29: 0.24659197 | G29: 0.2618003 | H29: 0.26383604 | I29: 0.25196124
A30: 9 | B30: 0.26685211 | C30: 0.29439631 | D30: 0.32810302 | E30: 0.29145119 | F30: 0.26685211 | G30: 0.26306787 | H30: 0.25678063 | I30: 0.24869074
A31: 8 | B31: 0.28684926 | C31: 0.24618135 | D31: 0.18336672 | E31: 0.22335578 | F31: 0.28684926 | G31: 0.27788914 | H31: 0.28287399 | I31: 0.27779568
A32: 7 | B32: 0.11602134 | C32: 0.037709941 | D32: 0.10606307 | E32: 0.1384544 | F32: 0.11602134 | G32: 0.11859276 | H32: 0.10077795 | I32: 0.10463331
A33: 6 | B33: 0.050271048 | C33: 0 | D33: 0.041565435 | E33: 0.04881453 | F33: 0.050271048 | G33: 0.041566955 | H33: 0.033017907 | I33: 0.043605856
A34: 5 | B34: 0.033414268 | C34: 0.086057184 | D34: 0.073697908 | E34: 0.046198587 | F34: 0.033414268 | G34: 0.037082971 | H34: 0.056081123 | I34: 0.054296797
A35: 4 | B35: 0 | C35: 0 | D35: 0 | E35: 0 | F35: 0 | G35: 0 | H35: 0 | I35: 0.0056585511
A36: 3 | B36: 0 | C36: 0 | D36: 0 | E36: 0 | F36: 0 | G36: 0 | H36: 0 | I36: 0
... A39: Extremely Unlikely | B39: 0 | C39: 0 | D39: 0 | E39: 0 | F39: 0 | G39: 0 | H39: 0 | I39: 0
A40: Mean | B40: =(B26-B28)*100 -> 42.975877 | C40: =(C26-C28)*100 -> 54.399434 | D40: =(D26-D28)*100 -> 48.004353 | E40: =(E26-E28)*100 -> 44.816359 | F40: =(F26-F28)*100 -> 42.975877 | G40: 44.621825 | H40: 42.488528 | I40: 38.373295
A43: Investment NPS: Commonwealth Bank | B43: All | C43: Apr 2025 - Sep 2025 | D43: May 2025 - Oct 2025 | E43: June 2025 - Nov 2025 | F43: July 2025 - Dec 2025 | G43: August 2025 - Jan 2026 | H43: Sep 2025 - Feb 2026 | I43: Oct 2025 - Mar 2026
A44: Unweighted N | B44: 268 | C44: 66 | D44: 135 | E44: 199 | F44: 268 | G44: 331 | H44: 401 | I44: 391
A45: Promoter | B45: 0.53682547 | C45: 0.50680944 | D45: 0.54133151 | E45: 0.55748607 | F45: 0.53682547 | G45: 0.5501922 | H45: 0.54792716 | I45: 0.55717797
A46: Passive | B46: 0.33359332 | C46: 0.33747057 | D46: 0.35295168 | E46: 0.32056232 | F46: 0.33359332 | G46: 0.33680904 | H46: 0.33138707 | I46: 0.32494292
A47: Detractor | B47: 0.12958121 | C47: 0.15571999 | D47: 0.10571682 | E47: 0.12195161 | F47: 0.12958121 | G47: 0.11299876 | H47: 0.12068576 | I47: 0.11787911
A48: Extremely Likely | B48: 0.29650351 | C48: 0.31053977 | D48: 0.31320032 | E48: 0.30909499 | F48: 0.29650351 | G48: 0.314311 | H48: 0.30747943 | I48: 0.31299308
A49: 9 | B49: 0.24032196 | C49: 0.19626967 | D49: 0.22813118 | E49: 0.24839107 | F49: 0.24032196 | G49: 0.23588121 | H49: 0.24044774 | I49: 0.24418489
...

Sheet Belgium (quarter)
B2: Source: Global NPS tracking / Toluna | C2: Q4 - 2025
B4: Rolling NPS Data - Total
B5: ING
B6: NPS - ING (%) | C6: ='Belgium (Month)'!#REF! -> #REF!
B7: Rank - ING | C7: =C41 -> #REF!
B8: Promoter - ING (%) | C8: ='Belgium (Month)'!#REF! -> #REF!
B9: Passive - ING (%) | C9: ='Belgium (Month)'!#REF! -> #REF!
B10: Detractor - ING (%) | C10: ='Belgium (Month)'!#REF! -> #REF!
B12: Key competitors
B13: Belfius
B14: NPS - Belfius (%) | C14: ='Belgium (Month)'!#REF! -> #REF!
B15: Rank - Belfius | C15: =C42 -> #REF!
B16: Promoter - Belfius (%) | C16: ='Belgium (Month)'!#REF! -> #REF!
B17: Passive - Belfius (%) | C17: ='Belgium (Month)'!#REF! -> #REF!
B18: Detractor - Belfius (%) | C18: ='Belgium (Month)'!#REF! -> #REF!
B20: BNP Paribas Fortis
B21: NPS - BNP Paribas Fortis (%) | C21: ='Belgium (Month)'!#REF! -> #REF!
B22: Rank - BNP Paribas Fortis | C22: =C43 -> #REF!
B23: Promoter - BNP Paribas Fortis (%) | C23: ='Belgium (Month)'!#REF! -> #REF!
B24: Passive - BNP Paribas Fortis (%) | C24: ='Belgium (Month)'!#REF! -> #REF!
B25: Detractor - BNP Paribas Fortis (%) | C25: ='Belgium (Month)'!#REF! -> #REF!
B27: KBC/CBC
B28: NPS - KBC/CBC (%) | C28: ='Belgium (Month)'!#REF! -> #REF!
B29: Rank - KBC/CBC | C29: =C44 -> #REF!
B30: Promoter - KBC/CBC (%) | C30: ='Belgium (Month)'!#REF! -> #REF!
B31: Passive - KBC/CBC (%) | C31: ='Belgium (Month)'!#REF! -> #REF!
B32: Detractor - KBC/CBC (%) | C32: ='Belgium (Month)'!#REF! -> #REF!
B34: NPS - ING & Key competitors (For ranking)
B35: ING | C35: =C6 -> #REF!
B36: Belfius | C36: =C14 -> #REF!
B37: BNP Paribas Fortis | C37: =C21 -> #REF!
B38: KBC/CBC | C38: =C28 -> #REF!
B40: Ranking formule
B41: ING | C41: =RANK(C35,C$35:C$38,0) -> #REF!
B42: Belfius | C42: =RANK(C36,C$35:C$38,0) -> #REF!
B43: BNP Paribas Fortis | C43: =RANK(C37,C$35:C$38,0) -> #REF!
B44: KBC/CBC | C44: =RANK(C38,C$35:C$38,0) -> #REF!
B46: Base Size - NPS
B47: ING | C47: ='Belgium (Month)'!#REF! -> #REF!
B48: Belfius | C48: ='Belgium (Month)'!#REF! -> #REF!
...

Sheet Belgium (Month)
B2: Source: Global NPS tracking / Toluna | C2: January - 2026 (6 months rolling) | D2: February - 2026 (6 months rolling) | E2: March - 2026 (6 months rolling)
B4: NPS total
B5: ING | C5: NPS | D5: NPS | E5: NPS
C6: ='Belgium Crunch Output'!G21 -> 11.545893 | D6: ='Belgium Crunch Output'!H21 -> 10.763037 | E6: ='Belgium Crunch Output'!I21 -> 8.5654767
B7: Promoter | C7: ='Belgium Crunch Output'!G7 -> 0.31415111 | D7: ='Belgium Crunch Output'!H7 -> 0.31045631 | E7: ='Belgium Crunch Output'!I7 -> 0.29914663
B8: Passive | C8: ='Belgium Crunch Output'!G8 -> 0.4871567 | D8: ='Belgium Crunch Output'!H8 -> 0.48671774 | E8: ='Belgium Crunch Output'!I8 -> 0.48736151
B9: Detractor | C9: ='Belgium Crunch Output'!G9 -> 0.19869219 | D9: ='Belgium Crunch Output'!H9 -> 0.20282594 | E9: ='Belgium Crunch Output'!I9 -> 0.21349186
B10: Extremely likely | C10: ='Belgium Crunch Output'!G10 -> 0.14144933 | D10: ='Belgium Crunch Output'!H10 -> 0.14502576 | E10: ='Belgium Crunch Output'!I10 -> 0.13958879
B11: 9 | C11: ='Belgium Crunch Output'!G11 -> 0.17270178 | D11: ='Belgium Crunch Output'!H11 -> 0.16543056 | E11: ='Belgium Crunch Output'!I11 -> 0.15955784
B12: 8 | C12: ='Belgium Crunch Output'!G12 -> 0.26505588 | D12: ='Belgium Crunch Output'!H12 -> 0.28799723 | E12: ='Belgium Crunch Output'!I12 -> 0.29772607
B13: 7 | C13: ='Belgium Crunch Output'!G13 -> 0.22210082 | D13: ='Belgium Crunch Output'!H13 -> 0.19872051 | E13: ='Belgium Crunch Output'!I13 -> 0.18963544
B14: 6 | C14: ='Belgium Crunch Output'!G14 -> 0.079837675 | D14: ='Belgium Crunch Output'!H14 -> 0.079468581 | E14: ='Belgium Crunch Output'!I14 -> 0.088541413
B15: 5 | C15: ='Belgium Crunch Output'!G15 -> 0.060253928 | D15: ='Belgium Crunch Output'!H15 -> 0.064047883 | E15: ='Belgium Crunch Output'!I15 -> 0.070197316
B16: 4 | C16: ='Belgium Crunch Output'!G16 -> 0.0093464287 | D16: ='Belgium Crunch Output'!H16 -> 0.011521884 | E16: ='Belgium Crunch Output'!I16 -> 0.0081749518
B17: 3 | C17: ='Belgium Crunch Output'!G17 -> 0.017404717 | D17: ='Belgium Crunch Output'!H17 -> 0.014243653 | E17: ='Belgium Crunch Output'!I17 -> 0.013844497
B18: 2 | C18: ='Belgium Crunch Output'!G18 -> 0.0039800205 | D18: ='Belgium Crunch Output'!H18 -> 0.0069977466 | E18: ='Belgium Crunch Output'!I18 -> 0.010389363
B19: 1 | C19: ='Belgium Crunch Output'!G19 -> 0.015620898 | D19: ='Belgium Crunch Output'!H19 -> 0.012783814 | E19: ='Belgium Crunch Output'!I19 -> 0.012425567
B20: Extremely Unlikely | C20: ='Belgium Crunch Output'!G20 -> 0.012248519 | D20: ='Belgium Crunch Output'!H20 -> 0.013762381 | E20: ='Belgium Crunch Output'!I20 -> 0.0099187547
B21: n | C21: ='Belgium Crunch Output'!G6 -> 219 | D21: ='Belgium Crunch Output'!H6 -> 268 | E21: ='Belgium Crunch Output'!I6 -> 275
B23: Belfius | C23: NPS | D23: NPS | E23: NPS
C24: ='Belgium Crunch Output'!G40 -> 14.414706 | D24: ='Belgium Crunch Output'!H40 -> 12.472744 | E24: ='Belgium Crunch Output'!I40 -> 12.901733
B25: Promoter | C25: ='Belgium Crunch Output'!G26 -> 0.31699818 | D25: ='Belgium Crunch Output'!H26 -> 0.32070746 | E25: ='Belgium Crunch Output'!I26 -> 0.330788
B26: Passive | C26: ='Belgium Crunch Output'!G27 -> 0.51015071 | D26: ='Belgium Crunch Output'!H27 -> 0.48331252 | E26: ='Belgium Crunch Output'!I27 -> 0.46744133
B27: Detractor | C27: ='Belgium Crunch Output'!G28 -> 0.17285111 | D27: ='Belgium Crunch Output'!H28 -> 0.19598002 | E27: ='Belgium Crunch Output'!I28 -> 0.20177067
B28: Extremely likely | C28: ='Belgium Crunch Output'!G29 -> 0.13346918 | D28: ='Belgium Crunch Output'!H29 -> 0.14031488 | E28: ='Belgium Crunch Output'!I29 -> 0.14339854
B29: 9 | C29: ='Belgium Crunch Output'!G30 -> 0.18352899 | D29: ='Belgium Crunch Output'!H30 -> 0.18039258 | E29: ='Belgium Crunch Output'!I30 -> 0.18738947
B30: 8 | C30: ='Belgium Crunch Output'!G31 -> 0.32402977 | D30: ='Belgium Crunch Output'!H31 -> 0.30842649 | E30: ='Belgium Crunch Output'!I31 -> 0.30866656
B31: 7 | C31: ='Belgium Crunch Output'!G32 -> 0.18612094 | D31: ='Belgium Crunch Output'!H32 -> 0.17488604 | E31: ='Belgium Crunch Output'!I32 -> 0.15877477
B32: 6 | C32: ='Belgium Crunch Output'!G33 -> 0.066691949 | D32: ='Belgium Crunch Output'!H33 -> 0.06986287 | E32: ='Belgium Crunch Output'!I33 -> 0.067553118
B33: 5 | C33: ='Belgium Crunch Output'!G34 -> 0.050741542 | D33: ='Belgium Crunch Output'!H34 -> 0.056580513 | E33: ='Belgium Crunch Output'!I34 -> 0.06491622
B34: 4 | C34: ='Belgium Crunch Output'!G35 -> 0.016608146 | D34: ='Belgium Crunch Output'!H35 -> 0.01719166 | E34: ='Belgium Crunch Output'!I35 -> 0.017508387
B35: 3 | C35: ='Belgium Crunch Output'!G36 -> 0.011581171 | D35: ='Belgium Crunch Output'!H36 -> 0.011453669 | E35: ='Belgium Crunch Output'!I36 -> 0.011477302
B36: 2 | C36: ='Belgium Crunch Output'!G37 -> 0.014175944 | D36: ='Belgium Crunch Output'!H37 -> 0.014973967 | E36: ='Belgium Crunch Output'!I37 -> 0.015316663
B37: 1 | C37: ='Belgium Crunch Output'!G38 -> 0 | D37: ='Belgium Crunch Output'!H38 -> 0.0053344526 | E37: ='Belgium Crunch Output'!I38 -> 0.0054565377
B38: Extremely Unlikely | C38: ='Belgium Crunch Output'!G39 -> 0.01305236 | D38: ='Belgium Crunch Output'!H39 -> 0.020582887 | E38: ='Belgium Crunch Output'!I39 -> 0.01954244
B39: n | C39: ='Belgium Crunch Output'!G25 -> 451 | D39: ='Belgium Crunch Output'!H25 -> 544 | E39: ='Belgium Crunch Output'!I25 -> 530
B41: BNP Paribas Fortis | C41: NPS | D41: NPS | E41: NPS
C42: ='Belgium Crunch Output'!G59 -> 13.642026 | D42: ='Belgium Crunch Output'!H59 -> 10.35423 | E42: ='Belgium Crunch Output'!I59 -> 14.946107
B43: Promoter | C43: ='Belgium Crunch Output'!G45 -> 0.35039206 | D43: ='Belgium Crunch Output'!H45 -> 0.3312292 | E43: ='Belgium Crunch Output'!I45 -> 0.3672793
B44: Passive | C44: ='Belgium Crunch Output'!G46 -> 0.43563614 | D44: ='Belgium Crunch Output'!H46 -> 0.4410839 | E44: ='Belgium Crunch Output'!I46 -> 0.41490247
...

Sheet Belgium Crunch Output
A1: P97511: ING BAM Belgium
A2: Investment NPS
A3: Based on your knowledge and experience with the investment services offered by the brand(s) below, how likely is it that you would recommend their investment services to a friend, family member or colleague?
A5: Investment NPS: ING | B5: All | C5: Apr 2025 - Sep 2025 | D5: May 2025 - Oct 2025 | E5: June 2025 - Nov 2025 | F5: July 2025 - Dec 2025 | G5: Aug 2025 - Jan 2026 | H5: Sep 2025 - Feb 2026 | I5: Oct 2025 - Mar 2026
A6: Unweighted N | B6: 172 | C6: 41 | D6: 85 | E6: 130 | F6: 172 | G6: 219 | H6: 268 | I6: 275
A7: Promoter | B7: 0.32505318 | C7: 0.34409657 | D7: 0.36205785 | E7: 0.32131414 | F7: 0.32505318 | G7: 0.31415111 | H7: 0.31045631 | I7: 0.29914663
A8: Passive | B8: 0.49329913 | C8: 0.54057805 | D8: 0.50468665 | E8: 0.49925155 | F8: 0.49329913 | G8: 0.4871567 | H8: 0.48671774 | I8: 0.48736151
A9: Detractor | B9: 0.18164769 | C9: 0.11532538 | D9: 0.1332555 | E9: 0.17943431 | F9: 0.18164769 | G9: 0.19869219 | H9: 0.20282594 | I9: 0.21349186
A10: Extremely Likely | B10: 0.14480053 | C10: 0.13385802 | D10: 0.17667753 | E10: 0.14692229 | F10: 0.14480053 | G10: 0.14144933 | H10: 0.14502576 | I10: 0.13958879
A11: 9 | B11: 0.18025265 | C11: 0.21023855 | D11: 0.18538032 | E11: 0.17439185 | F11: 0.18025265 | G11: 0.17270178 | H11: 0.16543056 | I11: 0.15955784
A12: 8 | B12: 0.27502123 | C12: 0.31864751 | D12: 0.2848508 | E12: 0.2921581 | F12: 0.27502123 | G12: 0.26505588 | H12: 0.28799723 | I12: 0.29772607
A13: 7 | B13: 0.2182779 | C13: 0.22193054 | D13: 0.21983585 | E13: 0.20709345 | F13: 0.2182779 | G13: 0.22210082 | H13: 0.19872051 | I13: 0.18963544
A14: 6 | B14: 0.0712211 | C14: 0.05004105 | D14: 0.055713539 | E14: 0.064393471 | F14: 0.0712211 | G14: 0.079837675 | H14: 0.079468581 | I14: 0.088541413
A15: 5 | B15: 0.063950716 | C15: 0.021105745 | D15: 0.046451557 | E15: 0.059848858 | F15: 0.063950716 | G15: 0.060253928 | H15: 0.064047883 | I15: 0.070197316
A16: 4 | B16: 0.011859438 | C16: 0.020610627 | D16: 0.0097450185 | E16: 0.015708289 | F16: 0.011859438 | G16: 0.0093464287 | H16: 0.011521884 | I16: 0.0081749518
A17: 3 | B17: 0.015155108 | C17: 0 | D17: 0 | E17: 0.020073532 | F17: 0.015155108 | G17: 0.017404717 | H17: 0.014243653 | I17: 0.013844497
... A21: Mean | B21: 14.340549 | C21: 22.877119 | D21: 22.880235 | E21: 14.187983 | F21: 14.340549 | G21: 11.545893 | H21: 10.763037 | I21: 8.5654767
A24: Investment NPS: Belfius | B24: All | C24: Apr 2025 - Sep 2025 | D24: May 2025 - Oct 2025 | E24: June 2025 - Nov 2025 | F24: July 2025 - Dec 2025 | G24: Aug 2025 - Jan 2026 | H24: Sep 2025 - Feb 2026 | I24: Oct 2025 - Mar 2026
A25: Unweighted N | B25: 360 | C25: 92 | D25: 174 | E25: 270 | F25: 360 | G25: 451 | H25: 544 | I25: 530
A26: Promoter | B26: 0.32471416 | C26: 0.29196114 | D26: 0.29014365 | E26: 0.30856513 | F26: 0.32471416 | G26: 0.31699818 | H26: 0.32070746 | I26: 0.330788
A27: Passive | B27: 0.50139666 | C27: 0.53892473 | D27: 0.5260559 | E27: 0.51757217 | F27: 0.50139666 | G27: 0.51015071 | H27: 0.48331252 | I27: 0.46744133
A28: Detractor | B28: 0.17388918 | C28: 0.16911413 | D28: 0.18380045 | E28: 0.1738627 | F28: 0.17388918 | G28: 0.17285111 | H28: 0.19598002 | I28: 0.20177067
A29: Extremely Likely | B29: 0.1433897 | C29: 0.11191759 | D29: 0.12924574 | E29: 0.1532546 | F29: 0.1433897 | G29: 0.13346918 | H29: 0.14031488 | I29: 0.14339854
A30: 9 | B30: 0.18132446 | C30: 0.18004356 | D30: 0.16089792 | E30: 0.15531053 | F30: 0.18132446 | G30: 0.18352899 | H30: 0.18039258 | I30: 0.18738947
A31: 8 | B31: 0.31725884 | C31: 0.32001618 | D31: 0.32267511 | E31: 0.31546133 | F31: 0.31725884 | G31: 0.32402977 | H31: 0.30842649 | I31: 0.30866656
A32: 7 | B32: 0.18413782 | C32: 0.21890855 | D32: 0.20338079 | E32: 0.20211084 | F32: 0.18413782 | G32: 0.18612094 | H32: 0.17488604 | I32: 0.15877477
A33: 6 | B33: 0.065423313 | C33: 0.090404755 | D33: 0.082058914 | E33: 0.065841999 | F33: 0.065423313 | G33: 0.066691949 | H33: 0.06986287 | I33: 0.067553118
A34: 5 | B34: 0.058705311 | C34: 0.035491963 | D34: 0.055939492 | E34: 0.06363684 | F34: 0.058705311 | G34: 0.050741542 | H34: 0.056580513 | I34: 0.06491622
A35: 4 | B35: 0.015213173 | C35: 0.011174387 | D35: 0.010612084 | E35: 0.01324207 | F35: 0.015213173 | G35: 0.016608146 | H35: 0.01719166 | I35: 0.017508387
A36: 3 | B36: 0.0088407325 | C36: 0.012614794 | D36: 0.013657726 | E36: 0.0086334458 | F36: 0.0088407325 | G36: 0.011581171 | H36: 0.011453669 | I36: 0.011477302
... A40: Mean | B40: 15.082498 | C40: 12.284702 | D40: 10.63432 | E40: 13.470243 | F40: 15.082498 | G40: 14.414706 | H40: 12.472744 | I40: 12.901733
A43: Investment NPS: BNP Paribas Fortis | B43: All | C43: Apr 2025 - Sep 2025 | D43: May 2025 - Oct 2025 | E43: June 2025 - Nov 2025 | F43: July 2025 - Dec 2025 | G43: Aug 2025 - Jan 2026 | H43: Sep 2025 - Feb 2026 | I43: Oct 2025 - Mar 2026
A44: Unweighted N | B44: 360 | C44: 94 | D44: 184 | E44: 270 | F44: 360 | G44: 455 | H44: 546 | I44: 532
A45: Promoter | B45: 0.35028565 | C45: 0.26039857 | D45: 0.33191417 | E45: 0.34394523 | F45: 0.35028565 | G45: 0.35039206 | H45: 0.3312292 | I45: 0.3672793
A46: Passive | B46: 0.43759051 | C46: 0.470285 | D46: 0.44181665 | E46: 0.42855254 | F46: 0.43759051 | G46: 0.43563614 | H46: 0.4410839 | I46: 0.41490247
A47: Detractor | B47: 0.21212383 | C47: 0.26931642 | D47: 0.22626918 | E47: 0.22750223 | F47: 0.21212383 | G47: 0.2139718 | H47: 0.2276869 | I47: 0.21781823
A48: Extremely Likely | B48: 0.16491235 | C48: 0.15640409 | D48: 0.16821658 | E48: 0.16956951 | F48: 0.16491235 | G48: 0.1678391 | H48: 0.14660326 | I48: 0.16017442
A49: 9 | B49: 0.1853733 | C49: 0.10399449 | D49: 0.16369759 | E49: 0.17437572 | F49: 0.1853733 | G49: 0.18255296 | H49: 0.18462594 | I49: 0.20710488
A50: 8 | B50: 0.28694448 | C50: 0.30814693 | D50: 0.26243806 | E50: 0.27572688 | F50: 0.28694448 | G50: 0.2831717 | H50: 0.27931575 | I50: 0.2544326
A51: 7 | B51: 0.15064603 | C51: 0.16213807 | D51: 0.17937859 | E51: 0.15282566 | F51: 0.15064603 | G51: 0.15246444 | H51: 0.16176815 | I51: 0.16046986
...

Sheet Germany (quarter)
B2: Source: Global NPS tracking / Toluna | C2: Q4 - 2025
B4: Rolling NPS Data - Total
B5: ING
B6: NPS - ING (%) | C6: ='Germany (Month)'!#REF! -> #REF!
B7: Rank - ING | C7: =C57 -> #REF!
B8: Promoter - ING (%) | C8: ='Germany (Month)'!#REF! -> #REF!
B9: Passive - ING (%) | C9: ='Germany (Month)'!#REF! -> #REF!
B10: Detractor - ING (%) | C10: ='Germany (Month)'!#REF! -> #REF!
B12: Key competitors
B13: Commerzbank
B14: NPS - Commerzbank (%) | C14: ='Germany (Month)'!#REF! -> #REF!
B15: Rank - Commerzbank | C15: =C58 -> #REF!
B16: Promoter - Commerzbank (%) | C16: ='Germany (Month)'!#REF! -> #REF!
B17: Passive - Commerzbank (%) | C17: ='Germany (Month)'!#REF! -> #REF!
B18: Detractor - Commerzbank (%) | C18: ='Germany (Month)'!#REF! -> #REF!
B20: DKB
B21: NPS - DKB (%) | C21: ='Germany (Month)'!#REF! -> #REF!
B22: Rank - DKB | C22: =C59 -> #REF!
B23: Promoter - DKB (%) | C23: ='Germany (Month)'!#REF! -> #REF!
B24: Passive - DKB (%) | C24: ='Germany (Month)'!#REF! -> #REF!
B25: Detractor - DKB (%) | C25: ='Germany (Month)'!#REF! -> #REF!
B27: Postbank
B28: NPS - Postbank (%) | C28: ='Germany (Month)'!#REF! -> #REF!
B29: Rank - Postbank | C29: =C60 -> #REF!
B30: Promoter - Postbank (%) | C30: ='Germany (Month)'!#REF! -> #REF!
B31: Passive - Postbank (%) | C31: ='Germany (Month)'!#REF! -> #REF!
B32: Detractor - Postbank (%) | C32: ='Germany (Month)'!#REF! -> #REF!
B34: Sparkasse
B35: NPS - Sparkasse (%) | C35: ='Germany (Month)'!#REF! -> #REF!
B36: Rank - Sparkasse | C36: =C61 -> #REF!
B37: Promoter - Sparkasse (%) | C37: ='Germany (Month)'!#REF! -> #REF!
B38: Passive - Sparkasse (%) | C38: ='Germany (Month)'!#REF! -> #REF!
B39: Detractor - Sparkasse (%) | C39: ='Germany (Month)'!#REF! -> #REF!
B41: VR-Banken
B42: NPS - VR-Banken (%) | C42: ='Germany (Month)'!#REF! -> #REF!
B43: Rank - VR-Banken | C43: =C62 -> #REF!
B44: Promoter - VR-Banken (%) | C44: ='Germany (Month)'!#REF! -> #REF!
B45: Passive - VR-Banken (%) | C45: ='Germany (Month)'!#REF! -> #REF!
B46: Detractor - VR-Banken (%) | C46: ='Germany (Month)'!#REF! -> #REF!
B48: NPS - ING & Key competitors (For ranking)
...

Sheet Germany (Month)
B2: Source: Global NPS tracking / Toluna | C2: January - 2026 (6 months rolling) | D2: February - 2026 (6 months rolling) | E2: March - 2026 (6 months rolling)
B4: NPS total
B5: ING | C5: NPS | D5: NPS | E5: NPS
C6: ='Germany Crunch Output'!G21 -> 37.351547 | D6: ='Germany Crunch Output'!H21 -> 40.748368 | E6: ='Germany Crunch Output'!I21 -> 38.60839
B7: Promoter | C7: ='Germany Crunch Output'!G7 -> 0.51919561 | D7: ='Germany Crunch Output'!H7 -> 0.53085983 | E7: ='Germany Crunch Output'!I7 -> 0.51806757
B8: Passive | C8: ='Germany Crunch Output'!G8 -> 0.33512425 | D8: ='Germany Crunch Output'!H8 -> 0.34576402 | E8: ='Germany Crunch Output'!I8 -> 0.34994875
B9: Detractor | C9: ='Germany Crunch Output'!G9 -> 0.14568014 | D9: ='Germany Crunch Output'!H9 -> 0.12337615 | E9: ='Germany Crunch Output'!I9 -> 0.13198368
B10: Extremely likely | C10: ='Germany Crunch Output'!G10 -> 0.29116013 | D10: ='Germany Crunch Output'!H10 -> 0.29674692 | E10: ='Germany Crunch Output'!I10 -> 0.28992646
B11: 9 | C11: ='Germany Crunch Output'!G11 -> 0.22803548 | D11: ='Germany Crunch Output'!H11 -> 0.23411291 | E11: ='Germany Crunch Output'!I11 -> 0.22814112
B12: 8 | C12: ='Germany Crunch Output'!G12 -> 0.25052702 | D12: ='Germany Crunch Output'!H12 -> 0.25709205 | E12: ='Germany Crunch Output'!I12 -> 0.25989679
B13: 7 | C13: ='Germany Crunch Output'!G13 -> 0.084597237 | D13: ='Germany Crunch Output'!H13 -> 0.088671967 | E13: ='Germany Crunch Output'!I13 -> 0.090051959
B14: 6 | C14: ='Germany Crunch Output'!G14 -> 0.058065004 | D14: ='Germany Crunch Output'!H14 -> 0.047857094 | E14: ='Germany Crunch Output'!I14 -> 0.046945298
B15: 5 | C15: ='Germany Crunch Output'!G15 -> 0.044852787 | D15: ='Germany Crunch Output'!H15 -> 0.036967604 | E15: ='Germany Crunch Output'!I15 -> 0.044694224
B16: 4 | C16: ='Germany Crunch Output'!G16 -> 0.0099705346 | D16: ='Germany Crunch Output'!H16 -> 0.0082177005 | E16: ='Germany Crunch Output'!I16 -> 0.00824947
B17: 3 | C17: ='Germany Crunch Output'!G17 -> 0.0092906878 | D17: ='Germany Crunch Output'!H17 -> 0.0076573718 | E17: ='Germany Crunch Output'!I17 -> 0.0045689004
B18: 2 | C18: ='Germany Crunch Output'!G18 -> 0 | D18: ='Germany Crunch Output'!H18 -> 0 | E18: ='Germany Crunch Output'!I18 -> 0.0037022419
B19: 1 | C19: ='Germany Crunch Output'!G19 -> 0 | D19: ='Germany Crunch Output'!H19 -> 0 | E19: ='Germany Crunch Output'!I19 -> 0
B20: Extremely Unlikely | C20: ='Germany Crunch Output'!G20 -> 0.023501126 | D20: ='Germany Crunch Output'!H20 -> 0.022676378 | E20: ='Germany Crunch Output'!I20 -> 0.023823543
B21: n | C21: ='Germany Crunch Output'!G6 -> 210 | D21: ='Germany Crunch Output'!H6 -> 255 | E21: ='Germany Crunch Output'!I6 -> 256
B23: Commerzbank | C23: NPS | D23: NPS | E23: NPS
C24: Low N | D24: ='Germany Crunch Output'!H97 -> 27.770398 | E24: ='Germany Crunch Output'!I97 -> 25.112411
B25: Promoter | C25: Low N | D25: ='Germany Crunch Output'!H83 -> 0.49966714 | E25: ='Germany Crunch Output'!I83 -> 0.46763512
B26: Passive | C26: Low N | D26: ='Germany Crunch Output'!H84 -> 0.2783697 | E26: ='Germany Crunch Output'!I84 -> 0.31585386
B27: Detractor | C27: Low N | D27: ='Germany Crunch Output'!H85 -> 0.22196316 | E27: ='Germany Crunch Output'!I85 -> 0.21651102
B28: Extremely likely | C28: Low N | D28: ='Germany Crunch Output'!H86 -> 0.2519732 | E28: ='Germany Crunch Output'!I86 -> 0.2666574
B29: 9 | C29: Low N | D29: ='Germany Crunch Output'!H87 -> 0.24769394 | E29: ='Germany Crunch Output'!I87 -> 0.20097772
B30: 8 | C30: Low N | D30: ='Germany Crunch Output'!H88 -> 0.1396274 | E30: ='Germany Crunch Output'!I88 -> 0.18333383
B31: 7 | C31: Low N | D31: ='Germany Crunch Output'!H89 -> 0.1387423 | E31: ='Germany Crunch Output'!I89 -> 0.13252003
B32: 6 | C32: Low N | D32: ='Germany Crunch Output'!H90 -> 0.058508877 | E32: ='Germany Crunch Output'!I90 -> 0.06451441
B33: 5 | C33: Low N | D33: ='Germany Crunch Output'!H91 -> 0.089564336 | E33: ='Germany Crunch Output'!I91 -> 0.098267876
B34: 4 | C34: Low N | D34: ='Germany Crunch Output'!H92 -> 0.00709068 | E34: ='Germany Crunch Output'!I92 -> 0
B35: 3 | C35: Low N | D35: ='Germany Crunch Output'!H93 -> 0.019832188 | E35: ='Germany Crunch Output'!I93 -> 0.019212811
B36: 2 | C36: Low N | D36: ='Germany Crunch Output'!H94 -> 0.010272294 | E36: ='Germany Crunch Output'!I94 -> 0.0099514808
B37: 1 | C37: Low N | D37: ='Germany Crunch Output'!H95 -> 0 | E37: ='Germany Crunch Output'!I95 -> 0
B38: Extremely Unlikely | C38: Low N | D38: ='Germany Crunch Output'!H96 -> 0.036694785 | E38: ='Germany Crunch Output'!I96 -> 0.024564438
B39: n | C39: ='Germany Crunch Output'!G82 -> 91 | D39: ='Germany Crunch Output'!H82 -> 106 | E39: ='Germany Crunch Output'!I82 -> 109
B41: DKB | C41: NPS | D41: NPS | E41: NPS
C42: Low N | D42: Low N | E42: Low N
B43: Promoter | C43: Low N | D43: Low N | E43: Low N
B44: Passive | C44: Low N | D44: Low N | E44: Low N
...

Sheet Germany Crunch Output
A1: P97511:ING BAM Germany
A2: Investment NPS
A3: Based on your knowledge and experience with the investment services offered by the brand(s) below, how likely is it that you would recommend their investment services to a friend, family member or colleague?
A5: Investment NPS: ING | B5: All | C5: Apr 2025 - Sep 2025 | D5: May 2025 - Oct 2025 | E5: June 2025 - Nov 2025 | F5: July 2025 - Dec 2025 | G5: Aug 2025 - Jan 2026 | H5: Sep 2025 - Feb 2026 | I5: Oct 2025 - Mar 2026
A6: Unweighted N | B6: 179 | C6: 48 | D6: 102 | E6: 138 | F6: 179 | G6: 210 | H6: 255 | I6: 256
A7: Promoter | B7: 0.49982677 | C7: 0.59465369 | D7: 0.53821203 | E7: 0.51833131 | F7: 0.49982677 | G7: 0.51919561 | H7: 0.53085983 | I7: 0.51806757
A8: Passive | B8: 0.36195482 | C8: 0.33156523 | D8: 0.38219667 | E8: 0.35693717 | F8: 0.36195482 | G8: 0.33512425 | H8: 0.34576402 | I8: 0.34994875
A9: Detractor | B9: 0.13821841 | C9: 0.073781077 | D9: 0.0795913 | E9: 0.12473152 | F9: 0.13821841 | G9: 0.14568014 | H9: 0.12337615 | I9: 0.13198368
A10: Extremely Likely | B10: 0.27003729 | C10: 0.30207186 | D10: 0.3017201 | E10: 0.26353875 | F10: 0.27003729 | G10: 0.29116013 | H10: 0.29674692 | I10: 0.28992646
A11: 9 | B11: 0.22978948 | C11: 0.29258183 | D11: 0.23649192 | E11: 0.25479255 | F11: 0.22978948 | G11: 0.22803548 | H11: 0.23411291 | I11: 0.22814112
A12: 8 | B12: 0.26741089 | C12: 0.23170057 | D12: 0.27930922 | E12: 0.25096076 | F12: 0.26741089 | G12: 0.25052702 | H12: 0.25709205 | I12: 0.25989679
A13: 7 | B13: 0.094543932 | C13: 0.099864668 | D13: 0.10288746 | E13: 0.10597641 | F13: 0.094543932 | G13: 0.084597237 | H13: 0.088671967 | I13: 0.090051959
A14: 6 | B14: 0.056904828 | C14: 0.023727159 | D14: 0.035248796 | E14: 0.057868592 | F14: 0.056904828 | G14: 0.058065004 | H14: 0.047857094 | I14: 0.046945298
A15: 5 | B15: 0.037391536 | C15: 0 | D15: 0.011994982 | E15: 0.027920486 | F15: 0.037391536 | G15: 0.044852787 | H15: 0.036967604 | I15: 0.044694224
A16: 4 | B16: 0.011759487 | C16: 0 | D16: 0 | E16: 0.014935276 | F16: 0.011759487 | G16: 0.0099705346 | H16: 0.0082177005 | I16: 0.00824947
A17: 3 | B17: 0.0044447653 | C17: 0.015897305 | D17: 0.0076063055 | E17: 0.0056451268 | F17: 0.0044447653 | G17: 0.0092906878 | H17: 0.0076573718 | I17: 0.0045689004
... A20: Extremely Unlikely | B20: 0.02771779 | C20: 0.034156613 | D20: 0.024741218 | E20: 0.018362043 | F20: 0.02771779 | G20: 0.023501126 | H20: 0.022676378 | I20: 0.023823543
A21: Mean | B21: =(B7-B9)*100 -> 36.160837 | C21: =(C7-C9)*100 -> 52.087261 | D21: =(D7-D9)*100 -> 45.862072 | E21: =(E7-E9)*100 -> 39.359978 | F21: =(F7-F9)*100 -> 36.160837 | G21: 37.351547 | H21: 40.748368 | I21: 38.60839
A24: Investment NPS: Sparkasse | B24: All | C24: Apr 2025 - Sep 2025 | D24: May 2025 - Oct 2025 | E24: June 2025 - Nov 2025 | F24: July 2025 - Dec 2025 | G24: Aug 2025 - Jan 2026 | H24: Sep 2025 - Feb 2026 | I24: Oct 2025 - Mar 2026
A25: Unweighted N | B25: 308 | C25: 67 | D25: 147 | E25: 233 | F25: 308 | G25: 383 | H25: 452 | I25: 436
A26: Promoter | B26: 0.44375588 | C26: 0.40871554 | D26: 0.47770192 | E26: 0.44773701 | F26: 0.44375588 | G26: 0.48349876 | H26: 0.49828598 | I26: 0.53151866
A27: Passive | B27: 0.38331787 | C27: 0.45918312 | D27: 0.40600108 | E27: 0.3964827 | F27: 0.38331787 | G27: 0.35735545 | H27: 0.33136582 | I27: 0.3028932
A28: Detractor | B28: 0.17292626 | C28: 0.13210134 | D28: 0.116297 | E28: 0.15578029 | F28: 0.17292626 | G28: 0.15914579 | H28: 0.1703482 | I28: 0.16558814
A29: Extremely Likely | B29: 0.26992314 | C29: 0.2705036 | D29: 0.27171775 | E29: 0.25228063 | F29: 0.26992314 | G29: 0.32349093 | H29: 0.32390662 | I29: 0.33963262
A30: 9 | B30: 0.17383274 | C30: 0.13821194 | D30: 0.20598417 | E30: 0.19545638 | F30: 0.17383274 | G30: 0.16000782 | H30: 0.17437936 | I30: 0.19188604
A31: 8 | B31: 0.24555671 | C31: 0.27062248 | D31: 0.24229781 | E31: 0.25036285 | F31: 0.24555671 | G31: 0.21736482 | H31: 0.20582978 | I31: 0.19003799
A32: 7 | B32: 0.13776115 | C32: 0.18856064 | D32: 0.16370327 | E32: 0.14611985 | F32: 0.13776115 | G32: 0.13999063 | H32: 0.12553604 | I32: 0.11285521
A33: 6 | B33: 0.053112821 | C33: 0.024013969 | D33: 0.017693052 | E33: 0.049476926 | F33: 0.053112821 | G33: 0.042752988 | H33: 0.051849746 | I33: 0.052367675
A34: 5 | B34: 0.074146775 | C34: 0.0663322 | D34: 0.068305486 | E34: 0.071128886 | F34: 0.074146775 | G34: 0.066935862 | H34: 0.068394665 | I34: 0.063291882
A35: 4 | B35: 0.014851227 | C35: 0.030325956 | D35: 0.019250753 | E35: 0.016039422 | F35: 0.014851227 | G35: 0.015048747 | H35: 0.014745305 | I35: 0.013260411
A36: 3 | B36: 0.012937344 | C36: 0 | D36: 0.0060040358 | E36: 0.011836461 | F36: 0.012937344 | G36: 0.015153648 | H36: 0.012838725 | I36: 0.013268837
... A39: Extremely Unlikely | B39: 0.012628498 | C39: 0 | D39: 0 | E39: 0.0040777413 | F39: 0.012628498 | G39: 0.012683601 | H39: 0.013026141 | I39: 0.015302747
A40: Mean | B40: =(B26-B28)*100 -> 27.082962 | C40: =(C26-C28)*100 -> 27.66142 | D40: =(D26-D28)*100 -> 36.140491 | E40: =(E26-E28)*100 -> 29.195673 | F40: =(F26-F28)*100 -> 27.082962 | G40: 32.435297 | H40: 32.793778 | I40: 36.593052
A43: Investment NPS: VR-Banken | B43: All | C43: Apr 2025 - Sep 2025 | D43: May 2025 - Oct 2025 | E43: June 2025 - Nov 2025 | F43: July 2025 - Dec 2025 | G43: Aug 2025 - Jan 2026 | H43: Sep 2025 - Feb 2026 | I43: Oct 2025 - Mar 2026
A44: Unweighted N | B44: 148 | C44: 39 | D44: 83 | E44: 115 | F44: 148 | G44: 177 | H44: 215 | I44: 217
A45: Promoter | B45: 0.43832769 | C45: 0.42788404 | D45: 0.42009849 | E45: 0.42863646 | F45: 0.43832769 | G45: 0.43804723 | H45: 0.43066902 | I45: 0.43301729
A46: Passive | B46: 0.36223448 | C46: 0.423846 | D46: 0.37463144 | E46: 0.3641071 | F46: 0.36223448 | G46: 0.34877233 | H46: 0.36984575 | I46: 0.35678535
A47: Detractor | B47: 0.19943783 | C47: 0.14826996 | D47: 0.20527008 | E47: 0.20725644 | F47: 0.19943783 | G47: 0.21318045 | H47: 0.19948523 | I47: 0.21019736
A48: Extremely Likely | B48: 0.3156411 | C48: 0.34297117 | D48: 0.32412114 | E48: 0.31105221 | F48: 0.3156411 | G48: 0.3127165 | H48: 0.29116759 | I48: 0.27108605
